package api

import (
	"context"
	"reflect"
	"testing"

	validator "github.com/go-playground/validator/v10"
)

// TestValidateSection_ByteBodyLine194 specifically targets the uncovered line 194
// This requires validator.Var to return an error that is NOT validator.ValidationErrors
func TestValidateSection_ByteBodyLine194(t *testing.T) {
	v := NewConventionValidator()

	// Create a situation where the validator will return an error during Var() call
	// that is not a ValidationErrors type. This is tricky because validator normally
	// returns ValidationErrors for validation failures.

	// One way is to cause a panic during validation which gets converted to an error
	field := reflect.StructField{
		Name: "Body",
		Type: reflect.TypeOf([]byte{}),
		Tag:  reflect.StructTag(`validate:"min=1"`), // Simple validation
	}

	// Create an invalid reflect.Value that will cause issues when Interface() is called
	// during validation. We'll use a value that has the right type but is invalid internally
	var bodyBytes []byte = nil
	_ = reflect.ValueOf(bodyBytes) // fieldValue - not used in this approach

	// Modify the value to make it invalid for Interface() call
	// We can't directly create an invalid value, but we can use a zero Value
	// Actually, let's try a different approach - create a value that looks like []byte
	// but will cause issues during validation

	// Create a fake slice value that will cause problems
	sliceType := reflect.SliceOf(reflect.TypeOf(byte(0)))
	// Create an invalid value by using zero Value of the right type
	_ = reflect.Zero(sliceType) // invalidValue - not used in this approach
	// Now make it unaddressable and invalid for Interface()
	// Actually this won't work either as Zero returns a valid zero value

	// Let's try yet another approach - we need the validator itself to panic
	// during the Var call, which then gets recovered and returned as a non-ValidationErrors error

	// The issue is at line 194 - the else clause after errors.As(err, &verrs) fails
	// This means v.validator.Var returned an error that's not ValidationErrors

	// Actually, looking at validateSection, there's a defer that recovers panics at line 200-204
	// But that's for the struct validation path, not the []byte path

	// For the []byte path (lines 182-198), there's no panic recovery
	// So if validator.Var panics, it will propagate up

	// Let's cause validator.Var to return a non-ValidationErrors error
	// This might happen if we pass something that causes an internal validator error

	// Actually, the validator wraps all errors in ValidationErrors, so we need to be creative
	// What if we mess with the validator's internal state?

	// Let's try registering a validator that causes issues
	v.GetValidator().RegisterValidation("testbad", func(fl validator.FieldLevel) bool {
		// Access something that will cause a panic
		// But this panic will be caught by the validator and wrapped
		return false
	})

	field2 := reflect.StructField{
		Name: "Body",
		Type: reflect.TypeOf([]byte{}),
		Tag:  reflect.StructTag(`validate:"testbad"`),
	}

	bodyBytes2 := []byte("test")
	fieldValue2 := reflect.ValueOf(bodyBytes2)

	validationErrors := make(map[string][]string)

	// This should go through the validator and add validation errors
	err := v.validateSection(context.Background(), field2, fieldValue2, validationErrors)
	if err != nil {
		t.Fatalf("unexpected error: %v", err)
	}

	// Should have validation errors
	if len(validationErrors["body"]) == 0 {
		t.Fatalf("expected validation errors for body")
	}

	// Now let's try to trigger the actual line 194
	// We need validator.Var to return something that's not ValidationErrors
	// The only way this can happen is if there's an internal validator error
	// or if we pass something that confuses the validator

	// Let's pass a nil reflect.Value
	var nilValue reflect.Value

	err2 := v.validateSection(context.Background(), field, nilValue, validationErrors)

	// This should trigger the panic recovery at line 200-204
	// But wait, that's for the struct path, not the []byte path

	// For []byte path, there's no panic recovery, so it will panic
	// Unless... the validator.Var itself handles the panic and returns an error

	if err2 != nil {
		t.Logf("got error from nil value: %v", err2)
	}
}
